//
//  Task+TimeoutTests.swift
//  FlyingFox
//
//  Created by Simon Whitty on 15/02/2022.
//  Copyright Â© 2022 Simon Whitty. All rights reserved.
//
//  Distributed under the permissive MIT license
//  Get the latest version from here:
//
//  https://github.com/swhitty/FlyingFox
//
//  Permission is hereby granted, free of charge, to any person obtaining a copy
//  of this software and associated documentation files (the "Software"), to deal
//  in the Software without restriction, including without limitation the rights
//  to use, copy, modify, merge, publish, distribute, sublicense, and/or sell
//  copies of the Software, and to permit persons to whom the Software is
//  furnished to do so, subject to the following conditions:
//
//  The above copyright notice and this permission notice shall be included in all
//  copies or substantial portions of the Software.
//
//  THE SOFTWARE IS PROVIDED "AS IS", WITHOUT WARRANTY OF ANY KIND, EXPRESS OR
//  IMPLIED, INCLUDING BUT NOT LIMITED TO THE WARRANTIES OF MERCHANTABILITY,
//  FITNESS FOR A PARTICULAR PURPOSE AND NONINFRINGEMENT. IN NO EVENT SHALL THE
//  AUTHORS OR COPYRIGHT HOLDERS BE LIABLE FOR ANY CLAIM, DAMAGES OR OTHER
//  LIABILITY, WHETHER IN AN ACTION OF CONTRACT, TORT OR OTHERWISE, ARISING FROM,
//  OUT OF OR IN CONNECTION WITH THE SOFTWARE OR THE USE OR OTHER DEALINGS IN THE
//  SOFTWARE.
//

@testable import FlyingFox
import XCTest

final class TaskTimeoutTests: XCTestCase {

    func testTimeoutReturnsSuccess_WhenTimeoutDoesNotExpire() async throws {
        // given
        let value = try await Task(timeout: 0.5) {
            "Fish"
        }.value

        // then
        XCTAssertEqual(value, "Fish")
    }

    func testTimeoutThrowsError_WhenTimeoutExpires() async {
        // given
        let task = Task<Void, Error>(timeout: 0.5) {
            try? await Task.sleep(nanoseconds: 10_000_000_000)
        }

        // then
        do {
            _ = try await task.value
            XCTFail("Expected TimeoutError")
        } catch {
            XCTAssertTrue(error is TimeoutError)
        }
    }


    func testTimeoutCancels() async {
        // given
        let task = Task(timeout: 0.5) {
            try await Task.sleep(nanoseconds: 10_000_000_000)
        }

        // when
        task.cancel()

        // then
        do {
            _ = try await task.value
            XCTFail("Expected CancellationError")
        } catch {
            XCTAssertTrue(error is CancellationError)
        }
    }
}
